<?xml version="1.0" encoding="utf-8"?>
<!-- This URDF was automatically created by SolidWorks to URDF Exporter! Originally created by Stephen Brawner (brawner@gmail.com) 
     Commit Version: 1.6.0-1-g15f4949  Build Version: 1.6.7594.29634
     For more information, please see http://wiki.ros.org/sw_urdf_exporter -->
<robot
  name="disco">
  <link
    name="base_link">
    <inertial>
      <origin
        xyz="-0.0577245160539221 0.00930438441947077 0.0504215490642201"
        rpy="0 0 0" />
      <mass
        value="0.0760060635936837" />
      <inertia
        ixx="1.9435707298114E-05"
        ixy="-1.326432259085E-07"
        ixz="-4.87335854153079E-07"
        iyy="3.30224471324617E-05"
        iyz="7.9553558702505E-08"
        izz="2.48720476713223E-05" />
    </inertial>
    <visual>
      <origin
        xyz="0 0 0"
        rpy="0 0 0" />
      <geometry>
        <mesh
          filename="package://disco/meshes/base_link.STL" />
      </geometry>
      <material
        name="">
        <color
          rgba="0.792156862745098 0.819607843137255 0.933333333333333 1" />
      </material>
    </visual>
    <collision>
      <origin
        xyz="0 0 0"
        rpy="0 0 0" />
      <geometry>
        <mesh
          filename="package://disco/meshes/base_link.STL" />
      </geometry>
    </collision>
  </link>
  <link
    name="link 1">
    <inertial>
      <origin
        xyz="0.025 0.0078084 3.4694E-18"
        rpy="0 0 0" />
      <mass
        value="0.0068021" />
      <inertia
        ixx="1.8206E-07"
        ixy="3.987E-22"
        ixz="4.7149E-23"
        iyy="1.6927E-06"
        iyz="3.3087E-24"
        izz="1.8009E-06" />
    </inertial>
    <visual>
      <origin
        xyz="0 0 0"
        rpy="0 0 0" />
      <geometry>
        <mesh
          filename="package://disco/meshes/link 1.STL" />
      </geometry>
      <material
        name="">
        <color
          rgba="0.79216 0.81961 0.93333 1" />
      </material>
    </visual>
    <collision>
      <origin
        xyz="0 0 0"
        rpy="0 0 0" />
      <geometry>
        <mesh
          filename="package://disco/meshes/link 1.STL" />
      </geometry>
    </collision>
  </link>
  <joint
    name="joint 1"
    type="continuous">
    <origin
      xyz="-0.033183 -0.044816 0.02141"
      rpy="-3.1306 0.098683 -0.088193" />
    <parent
      link="base_link" />
    <child
      link="link 1" />
    <axis
      xyz="0 1 0" />
  </joint>
</robot>